<?xml version="1.0"?>
<sdf version="1.4">
<model name="stewart_platform">
	
  <plugin name="joint_controller" filename="libjoint_controller.so"/>

  <joint name="proximal_link_1_joint" type="revolute">
		<parent>base_link</parent>
		<child>proximal_link_1</child>
		<pose>-0.06 0 0 0 0 0</pose>
		<axis>
			<xyz>0.5000001943375613 -0.8660252915835662 0</xyz>
      <limit>
				<lower> -0.785398 </lower>
				<upper> 1.57079 </upper>
				<velocity> 1 </velocity>
			</limit>
      <dynamics>
      <damping>0.4</damping>
      <friction>0.04</friction>
    </dynamics>
		</axis>
	</joint>

  <joint name="proximal_link_2_joint" type="revolute">
		<parent>base_link</parent>
		<child>proximal_link_2</child>
		<pose>-0.06 0 0 0 0 0</pose>
		<axis>
			<xyz>0.5000001943375613 -0.8660252915835662 0</xyz>
      <limit>
				<lower> -0.785398 </lower>
				<upper> 1.57079 </upper>
				<velocity> 1 </velocity>
			</limit>
      <dynamics>
        <damping>0.4</damping>
        <friction>0.04</friction>
      </dynamics>
		</axis>
	</joint>

	<joint name="proximal_link_3_joint" type="revolute">
		<parent>base_link</parent>
		<child>proximal_link_3</child>
		<pose>-0.06 0 0 0 0 0</pose>
		<axis>
			<xyz>0.5000001943375613 0.8660252915835662 0</xyz>
      <limit>
				<lower> -0.785398 </lower>
				<upper> 1.57079 </upper>
				<velocity> 1 </velocity>
			</limit>
      <dynamics>
      <damping>0.4</damping>
      <friction>0.04</friction>
    </dynamics>
		</axis>
	</joint>

  <joint name="proximal_link_4_joint" type="revolute">
		<parent>base_link</parent>
		<child>proximal_link_4</child>
		<pose>-0.06 0 0 0 0 0</pose>
		<axis>
			<xyz>0.5000001943375613 0.8660252915835662 0</xyz>
      <limit>
				<lower> -0.785398 </lower>
				<upper> 1.57079 </upper>
				<velocity> 1 </velocity>
			</limit>
      <dynamics>
      <damping>0.4</damping>
      <friction>0.04</friction>
    </dynamics>
		</axis>
	</joint>

	<joint name="proximal_link_5_joint" type="revolute">
		<parent>base_link</parent>
		<child>proximal_link_5</child>
		<pose>-0.06 0 0 0 0 0</pose>
		<axis>
			<xyz>-1 0 0</xyz>
      <limit>
				<lower> -0.785398 </lower>
				<upper> 1.57079 </upper>
				<velocity> 1 </velocity>
			</limit>
      <dynamics>
      <damping>0.4</damping>
      <friction>0.04</friction>
    </dynamics>
		</axis>
	</joint>

  <joint name="proximal_link_6_joint" type="revolute">
		<parent>base_link</parent>
		<child>proximal_link_6</child>
		<pose>-0.06 0 0 0 0 0</pose>
		<axis>
			<xyz>-1 0 0</xyz>
      <limit>
				<lower> -0.785398 </lower>
				<upper> 1.57079 </upper>
				<velocity> 1 </velocity>
			</limit>
      <dynamics>
      <damping>0.4</damping>
      <friction>0.04</friction>
    </dynamics>
		</axis>
	</joint>

  <joint name="distal_link_1_joint" type="ball">
		<parent>proximal_link_1</parent>
		<child>distal_link_1</child>
		<pose> 0.135345 0 0 0 0 0</pose>
		<axis>
    <xyz>0 0 1</xyz>
      <dynamics>
      <damping>0.4</damping>
      <friction>0.04</friction>
    </dynamics>
		</axis>
    <axis2>
    <xyz>0 1 0</xyz>
      <dynamics>
      <damping>0.4</damping>
      <friction>0.04</friction>
    </dynamics>
		</axis2>
	</joint>

  <joint name="distal_link_2_joint" type="ball">
		<parent>proximal_link_2</parent>
		<child>distal_link_2</child>
		<pose> 0.135345 0 0 0 0 0</pose>
		<axis>
    <xyz>0 0 1</xyz>
      <dynamics>
      <damping>0.4</damping>
      <friction>0.04</friction>
    </dynamics>
		</axis>
    <axis2>
    <xyz>0 1 0</xyz>
      <dynamics>
      <damping>0.4</damping>
      <friction>0.04</friction>
    </dynamics>
		</axis2>
	</joint>

  <joint name="distal_link_3_joint" type="ball">
		<parent>proximal_link_3</parent>
		<child>distal_link_3</child>
		<pose> 0.135345 0 0 0 0 0</pose>
		<axis>
    <xyz>0 0 1</xyz>
      <dynamics>
      <damping>0.4</damping>
      <friction>0.04</friction>
    </dynamics>
		</axis>
    <axis2>
    <xyz>0 1 0</xyz>
      <dynamics>
      <damping>0.4</damping>
      <friction>0.04</friction>
    </dynamics>
		</axis2>
	</joint>

  <joint name="distal_link_4_joint" type="ball">
		<parent>proximal_link_4</parent>
		<child>distal_link_4</child>
		<pose> 0.135345 0 0 0 0 0</pose>
		<axis>
    <xyz>0 0 1</xyz>
      <dynamics>
      <damping>0.4</damping>
      <friction>0.04</friction>
    </dynamics>
		</axis>
    <axis2>
    <xyz>0 1 0</xyz>
      <dynamics>
      <damping>0.4</damping>
      <friction>0.04</friction>
    </dynamics>
		</axis2>
	</joint>

  <joint name="distal_link_5_joint" type="ball">
		<parent>proximal_link_5</parent>
		<child>distal_link_5</child>
		<pose> 0.135345 0 0 0 0 0</pose>
		<axis>
    <xyz>0 0 1</xyz>
      <dynamics>
      <damping>0.4</damping>
      <friction>0.04</friction>
    </dynamics>
		</axis>
    <axis2>
    <xyz>0 1 0</xyz>
      <dynamics>
      <damping>0.4</damping>
      <friction>0.04</friction>
    </dynamics>
		</axis2>
	</joint>

  <joint name="distal_link_6_joint" type="ball">
		<parent>proximal_link_6</parent>
		<child>distal_link_6</child>
		<pose> 0.135345 0 0 0 0 0</pose>
		<axis>
    <xyz>0 0 1</xyz>
      <dynamics>
      <damping>0.4</damping>
      <friction>0.04</friction>
    </dynamics>
		</axis>
    <axis2>
    <xyz>0 1 0</xyz>
      <dynamics>
      <damping>0.4</damping>
      <friction>0.04</friction>
    </dynamics>
		</axis2>
	</joint>

  <joint name="platform_link_1_joint" type="ball">
		<parent>distal_link_1</parent>
		<child>platform_link</child>
		<pose>0.06205127186683686 -0.007475938717505671 0 0 0 0</pose>
	</joint>

  <joint name="platform_link_2_joint" type="ball">
		<parent>distal_link_2</parent>
		<child>platform_link</child>
		<pose>0.02455125729151977 0.0574759581512618 0 0 0 0</pose>
	</joint>

  <joint name="platform_link_3_joint" type="ball">
		<parent>distal_link_3</parent>
		<child>platform_link</child>
		<pose>-0.02455125729151977 0.0574759581512618 0 0 0 0</pose>
	</joint>

  <joint name="platform_link_4_joint" type="ball">
		<parent>distal_link_4</parent>
		<child>platform_link</child>
		<pose>-0.06205127186683686 -0.007475938717505671 0 0 0 0</pose>
	</joint>

  <joint name="platform_link_5_joint" type="ball">
		<parent>distal_link_5</parent>
		<child>platform_link</child>
		<pose>-0.0375 -0.05 0 0 0 0</pose>
	</joint>

  <joint name="platform_link_6_joint" type="ball">
		<parent>distal_link_6</parent>
		<child>platform_link</child>
		<pose>0.0375 -0.05 0 0 0 0</pose>
  </joint>

  <joint name="nozzle_joint" type="fixed">
		<parent>platform_link</parent>
		<child>nozzle</child>
		<pose>0 0 0 0 0 0</pose>
	</joint>

  <link name="nozzle">
    <pose>0 0 0.2873294183952094 0 0 0</pose>
    <inertial>
    <mass>0.1</mass>
    <inertia>
      <ixx>9.333330000000002e-05</ixx>
      <ixy>0.0</ixy>
      <ixz>0.0</ixz>
      <iyy>9.333330000000002e-05</iyy> 
      <iyz>0.0</iyz>
      <izz>2.0e-05</izz>
    </inertia>
    </inertial>
    <!-- <collision name="collision">
      <geometry>
        <cylinder>
          <radius>0.02</radius>
          <length>0.1</length>
        </cylinder> 
      </geometry>
    </collision> -->
    <visual name="visual">
    <pose>0 0 0 0 0 0</pose>
      <geometry>
        <cylinder>
          <radius>0.02</radius>
          <length>0.1</length>
        </cylinder>
      </geometry>
      <material>
      <script>
        <name>Gazebo/Red</name>
        <uri>file://media/materials/scripts/gazebo.material</uri>
      </script>
      <shader type='pixel'>
        <normal_map>__default__</normal_map>
      </shader>
      <ambient>0.175 0.175 0.175 1</ambient>
      <diffuse>0.175 0.175 0.175 1</diffuse>
      <specular>0.175 0.175 0.175 1</specular>
      <emissive>0 0 0 1</emissive>
    </material>
    </visual>
  </link>

  <link name="base_link">
    <pose>0 0 0.02 0 0 0</pose>
    <inertial>
    <mass>0.1</mass>
    <inertia>
      <ixx>0.00021583332799999998</ixx>
      <ixy>0.0</ixy>
      <ixz>0.0</ixz>
      <iyy>0.00021583332799999998</iyy> 
      <iyz>0.0</iyz>
      <izz>0.000405</izz>
    </inertia>
    </inertial>
    <collision name="collision">
      <geometry>
        <cylinder>
          <radius>0.0915</radius>
          <length>0.04</length>
        </cylinder> 
      </geometry>
    </collision>
    <visual name="visual">
    <pose>-0.124 0.105 -0.02 0 0 -1.5708</pose>
      <geometry>
        <!-- <cylinder> -->
          <!-- <radius>0.0915</radius> -->
          <!-- <length>0.04</length> -->
        <!-- </cylinder> --> 
        <mesh>
          <uri>model://stewart_platform/meshes/Stuart_base.dae</uri>
          <scale> 0.001 0.001 0.001 </scale>
        </mesh>
      </geometry>
      <material>
      <script>
        <name>Gazebo/DarkGrey</name>
        <uri>file://media/materials/scripts/gazebo.material</uri>
      </script>
      <shader type='pixel'>
        <normal_map>__default__</normal_map>
      </shader>
      <ambient>0.175 0.175 0.175 1</ambient>
      <diffuse>0.175 0.175 0.175 1</diffuse>
      <specular>0.175 0.175 0.175 1</specular>
      <emissive>0 0 0 1</emissive>
    </material>
    </visual>
  </link>

  <link name="proximal_link_1">
    <pose>0.13815379694410468 0.06071061183950534 0.02 0 0 0.523599</pose>
    <inertial>
      <mass>0.02</mass>
      <inertia>
        <ixx>1.33333328e-06</ixx>
        <ixy>0.0</ixy>
        <ixz>0.0</ixz>
        <iyy>2.4666665679999998e-05</iyy> 
        <iyz>0.0</iyz>
        <izz>2.4666665679999998e-05</izz>
      </inertia>
    </inertial>
    <collision name="collision">
      <geometry>
        <box>
          <size>0.12 0.02 0.02</size>
        </box> 
      </geometry>
    </collision>
    <visual name="visual">
      <geometry>
        <box>
          <size>0.12 0.02 0.02</size>
        </box> 
      </geometry>
      <material>
      <script>
        <name>Gazebo/DarkGrey</name>
        <uri>file://media/materials/scripts/gazebo.material</uri>
      </script>
      <shader type='pixel'>
        <normal_map>__default__</normal_map>
      </shader>
      <ambient>0.175 0.175 0.175 1</ambient>
      <diffuse>0.175 0.175 0.175 1</diffuse>
      <specular>0.175 0.175 0.175 1</specular>
      <emissive>0 0 0 1</emissive>
    </material>
    </visual>
  </link>

  <link name="proximal_link_2">
    <pose>0.12165379053096516 0.08928944646176303 0.02 0 0 0.523599</pose>
    <inertial>
    <mass>0.02</mass>
    <inertia>
      <ixx>1.33333328e-06</ixx>
      <ixy>0.0</ixy>
      <ixz>0.0</ixz>
      <iyy>2.4666665679999998e-05</iyy> 
      <iyz>0.0</iyz>
      <izz>2.4666665679999998e-05</izz>
    </inertia>
    </inertial>
    <collision name="collision">
      <geometry>
        <box>
          <size>0.12 0.02 0.02</size>
        </box> 
      </geometry>
    </collision>
    <visual name = "visual">
      <geometry>
        <box>
          <size>0.12 0.02 0.02</size>
        </box> 
      </geometry>
      <material>
      <script>
        <name>Gazebo/DarkGrey</name>
        <uri>file://media/materials/scripts/gazebo.material</uri>
      </script>
      <shader type='pixel'>
        <normal_map>__default__</normal_map>
      </shader>
      <ambient>0.175 0.175 0.175 1</ambient>
      <diffuse>0.175 0.175 0.175 1</diffuse>
      <specular>0.175 0.175 0.175 1</specular>
      <emissive>0 0 0 1</emissive>
    </material>
    </visual>
  </link>

  <link name="proximal_link_3">
    <pose>-0.12165379053096516 0.08928944646176303 0.02 0 0 2.61799</pose>
    <inertial>
    <mass>0.02</mass>
    <inertia>
      <ixx>1.33333328e-06</ixx>
      <ixy>0.0</ixy>
      <ixz>0.0</ixz>
      <iyy>2.4666665679999998e-05</iyy> 
      <iyz>0.0</iyz>
      <izz>2.4666665679999998e-05</izz>
    </inertia>
    </inertial>
    <collision name="collision">
      <geometry>
        <box>
          <size>0.12 0.02 0.02</size>
        </box> 
      </geometry>
    </collision>
    <visual name = "visual">
      <geometry>
        <box>
          <size>0.12 0.02 0.02</size>
        </box> 
      </geometry>
      <material>
      <script>
        <name>Gazebo/DarkGrey</name>
        <uri>file://media/materials/scripts/gazebo.material</uri>
      </script>
      <shader type='pixel'>
        <normal_map>__default__</normal_map>
      </shader>
      <ambient>0.175 0.175 0.175 1</ambient>
      <diffuse>0.175 0.175 0.175 1</diffuse>
      <specular>0.175 0.175 0.175 1</specular>
      <emissive>0 0 0 1</emissive>
    </material>
    </visual>
  </link>

  <link name="proximal_link_4">
    <pose>-0.13815379694410468 0.06071061183950534 0.02 0 0 2.61799</pose>
    <inertial>
    <mass>0.02</mass>
    <inertia>
      <ixx>1.33333328e-06</ixx>
      <ixy>0.0</ixy>
      <ixz>0.0</ixz>
      <iyy>2.4666665679999998e-05</iyy> 
      <iyz>0.0</iyz>
      <izz>2.4666665679999998e-05</izz>
    </inertia>
    </inertial>
    <collision name="collision">
      <geometry>
        <box>
          <size>0.12 0.02 0.02</size>
        </box> 
      </geometry>
    </collision>
    <visual name = "visual">
      <geometry>
        <box>
          <size>0.12 0.02 0.02</size>
        </box> 
      </geometry>
      <material>
      <script>
        <name>Gazebo/DarkGrey</name>
        <uri>file://media/materials/scripts/gazebo.material</uri>
      </script>
      <shader type='pixel'>
        <normal_map>__default__</normal_map>
      </shader>
      <ambient>0.175 0.175 0.175 1</ambient>
      <diffuse>0.175 0.175 0.175 1</diffuse>
      <specular>0.175 0.175 0.175 1</specular>
      <emissive>0 0 0 1</emissive>
    </material>
    </visual>
  </link>

  <link name="proximal_link_5">
    <pose>-0.0165 -0.15 0.02 0 0 4.71239</pose>
    <inertial>
    <mass>0.02</mass>
    <inertia>
      <ixx>1.33333328e-06</ixx>
      <ixy>0.0</ixy>
      <ixz>0.0</ixz>
      <iyy>2.4666665679999998e-05</iyy> 
      <iyz>0.0</iyz>
      <izz>2.4666665679999998e-05</izz>
    </inertia>
    </inertial>
    <collision name="collision">
      <geometry>
        <box>
          <size>0.12 0.02 0.02</size>
        </box> 
      </geometry>
    </collision>
    <visual name = "visual">
      <geometry>
        <box>
          <size>0.12 0.02 0.02</size>
        </box> 
      </geometry>
      <material>
      <script>
        <name>Gazebo/DarkGrey</name>
        <uri>file://media/materials/scripts/gazebo.material</uri>
      </script>
      <shader type='pixel'>
        <normal_map>__default__</normal_map>
      </shader>
      <ambient>0.175 0.175 0.175 1</ambient>
      <diffuse>0.175 0.175 0.175 1</diffuse>
      <specular>0.175 0.175 0.175 1</specular>
      <emissive>0 0 0 1</emissive>
    </material>
    </visual>
  </link>

  <link name="proximal_link_6">
    <pose>0.0165 -0.15 0.02 0 0 4.71239</pose>
    <inertial>
    <mass>0.02</mass>
    <inertia>
      <ixx>1.33333328e-06</ixx>
      <ixy>0.0</ixy>
      <ixz>0.0</ixz>
      <iyy>2.4666665679999998e-05</iyy> 
      <iyz>0.0</iyz>
      <izz>2.4666665679999998e-05</izz>
    </inertia>
    </inertial>
    <collision name="collision">
      <geometry>
        <box>
          <size>0.12 0.02 0.02</size>
        </box> 
      </geometry>
    </collision>
    <visual name = "visual">
      <geometry>
        <box>
          <size>0.12 0.02 0.02</size>
        </box> 
      </geometry>
      <material>
      <script>
        <name>Gazebo/DarkGrey</name>
        <uri>file://media/materials/scripts/gazebo.material</uri>
      </script>
      <shader type='pixel'>
        <normal_map>__default__</normal_map>
      </shader>
      <ambient>0.175 0.175 0.175 1</ambient>
      <diffuse>0.175 0.175 0.175 1</diffuse>
      <specular>0.175 0.175 0.175 1</specular>
      <emissive>0 0 0 1</emissive>
    </material>
    </visual>
  </link>

  <link name="distal_link_1">
    <gravity>false</gravity>
    <pose>0.12608329315297775 0.041617342391126674 0.12866470919760473 -1.4744678787260812 0.9361796638175959 0.6541030331103883</pose>
    <inertial>
    <mass>0.05</mass>
    <inertia>
      <ixx>6.25e-07</ixx>
      <ixy>0.0</ixy>
      <ixz>0.0</ixz>
      <iyy>0.00030561686162820643</iyy> 
      <iyz>0.0</iyz>
      <izz>0.00030561686162820643</izz>
    </inertia>
    </inertial>
    <collision name="collision">
      <geometry>
        <box>
          <size>0.27069 0.01 0.01</size>
        </box> 
      </geometry>
    </collision>
    <visual name = "visual">
      <pose> 0 0 0 0 1.57075 0 </pose>
      <geometry>
        <cylinder>
          <radius>0.005</radius>
          <length>0.27069</length>
        </cylinder> 
      </geometry>
      <material>
      <script>
        <name>Gazebo/DarkGrey</name>
        <uri>file://media/materials/scripts/gazebo.material</uri>
      </script>
      <shader type='pixel'>
        <normal_map>__default__</normal_map>
      </shader>
      <ambient>0.175 0.175 0.175 1</ambient>
      <diffuse>0.175 0.175 0.175 1</diffuse>
      <specular>0.175 0.175 0.175 1</specular>
      <emissive>0 0 0 1</emissive>
    </material>
    </visual>
  </link>

  <link name="distal_link_2">
  <gravity>false</gravity>
    <pose>0.09908328265874945 0.08838270813663926 0.12866470919760473  -1.4744678787260812 0.9361796638175959 0.39309496688961176</pose>
    <inertial>
    <mass>0.05</mass>
    <inertia>
      <ixx>6.25e-07</ixx>
      <ixy>0.0</ixy>
      <ixz>0.0</ixz>
      <iyy>0.00030561686162820643</iyy> 
      <iyz>0.0</iyz>
      <izz>0.00030561686162820643</izz>
    </inertia>
    </inertial>
    <collision name="collision">
      <geometry>
        <box>
          <size>0.27069 0.01 0.01</size>
        </box> 
      </geometry>
    </collision>
    <visual name = "visual">
      <pose> 0 0 0 0 1.57075 0 </pose>
      <geometry>
        <cylinder>
          <radius>0.005</radius>
          <length>0.27069</length>
        </cylinder> 
      </geometry>
      <material>
      <script>
        <name>Gazebo/DarkGrey</name>
        <uri>file://media/materials/scripts/gazebo.material</uri>
      </script>
      <shader type='pixel'>
        <normal_map>__default__</normal_map>
      </shader>
      <ambient>0.175 0.175 0.175 1</ambient>
      <diffuse>0.175 0.175 0.175 1</diffuse>
      <specular>0.175 0.175 0.175 1</specular>
      <emissive>0 0 0 1</emissive>
    </material>
    </visual>
  </link>

  <link name="distal_link_3">
  <gravity>false</gravity>
    <pose>-0.09908328265874945 0.08838270813663926 0.12866470919760473  -1.4744678787260812 0.9361796638175959 2.748494033110388</pose>
    <inertial>
    <mass>0.05</mass>
    <inertia>
      <ixx>6.25e-07</ixx>
      <ixy>0.0</ixy>
      <ixz>0.0</ixz>
      <iyy>0.00030561686162820643</iyy> 
      <iyz>0.0</iyz>
      <izz>0.00030561686162820643</izz>
    </inertia>
    </inertial>
    <collision name="collision">
      <geometry>
        <box>
          <size>0.27069 0.01 0.01</size>
        </box> 
      </geometry>
    </collision>
    <visual name = "visual">
      <pose> 0 0 0 0 1.57075 0 </pose>
      <geometry>
        <cylinder>
          <radius>0.005</radius>
          <length>0.27069</length>
        </cylinder> 
      </geometry>
      <material>
      <script>
        <name>Gazebo/DarkGrey</name>
        <uri>file://media/materials/scripts/gazebo.material</uri>
      </script>
      <shader type='pixel'>
        <normal_map>__default__</normal_map>
      </shader>
      <ambient>0.175 0.175 0.175 1</ambient>
      <diffuse>0.175 0.175 0.175 1</diffuse>
      <specular>0.175 0.175 0.175 1</specular>
      <emissive>0 0 0 1</emissive>
    </material>
    </visual>
  </link>

  <link name="distal_link_4">
  <gravity>false</gravity>
    <pose>-0.12608329315297775 0.041617342391126674 0.12866470919760473  -1.4744678787260812 0.9361796638175959 2.4874859668896114</pose>
    <inertial>
    <mass>0.05</mass>
    <inertia>
      <ixx>6.25e-07</ixx>
      <ixy>0.0</ixy>
      <ixz>0.0</ixz>
      <iyy>0.00030561686162820643</iyy> 
      <iyz>0.0</iyz>
      <izz>0.00030561686162820643</izz>
    </inertia>
    </inertial>
    <collision name="collision">
      <geometry>
        <box>
          <size>0.27069 0.01 0.01</size>
        </box> 
      </geometry>
    </collision>
    <visual name = "visual">
      <pose> 0 0 0 0 1.57075 0 </pose>
      <geometry>
        <cylinder>
          <radius>0.005</radius>
          <length>0.27069</length>
        </cylinder> 
      </geometry>
      <material>
      <script>
        <name>Gazebo/DarkGrey</name>
        <uri>file://media/materials/scripts/gazebo.material</uri>
      </script>
      <shader type='pixel'>
        <normal_map>__default__</normal_map>
      </shader>
      <ambient>0.175 0.175 0.175 1</ambient>
      <diffuse>0.175 0.175 0.175 1</diffuse>
      <specular>0.175 0.175 0.175 1</specular>
      <emissive>0 0 0 1</emissive>
    </material>
    </visual>
  </link>

  <link name="distal_link_5">
  <gravity>false</gravity>
    <pose>-0.027 -0.13 0.12866470919760473  -1.4744678787260812 0.9361796638175959 4.8428940331103885</pose>
    <inertial>
    <mass>0.05</mass>
    <inertia>
      <ixx>6.25e-07</ixx>
      <ixy>0.0</ixy>
      <ixz>0.0</ixz>
      <iyy>0.00030561686162820643</iyy> 
      <iyz>0.0</iyz>
      <izz>0.00030561686162820643</izz>
    </inertia>
    </inertial>
    <collision name="collision">
      <geometry>
        <box>
          <size>0.27069 0.01 0.01</size>
        </box> 
      </geometry>
    </collision>
    <visual name = "visual">
      <pose> 0 0 0 0 1.57075 0 </pose>
      <geometry>
        <cylinder>
          <radius>0.005</radius>
          <length>0.27069</length>
        </cylinder> 
      </geometry>
      <material>
      <script>
        <name>Gazebo/DarkGrey</name>
        <uri>file://media/materials/scripts/gazebo.material</uri>
      </script>
      <shader type='pixel'>
        <normal_map>__default__</normal_map>
      </shader>
      <ambient>0.175 0.175 0.175 1</ambient>
      <diffuse>0.175 0.175 0.175 1</diffuse>
      <specular>0.175 0.175 0.175 1</specular>
      <emissive>0 0 0 1</emissive>
    </material>
    </visual>
  </link>

  <link name="distal_link_6">
  <gravity>false</gravity>
    <pose>0.027 -0.13 0.12866470919760473  -1.4744678787260812 0.9361796638175959 4.581885966889612</pose>
    <inertial>
    <mass>0.05</mass>
    <inertia>
      <ixx>6.25e-07</ixx>
      <ixy>0.0</ixy>
      <ixz>0.0</ixz>
      <iyy>0.00030561686162820643</iyy> 
      <iyz>0.0</iyz>
      <izz>0.00030561686162820643</izz>
    </inertia>
    </inertial>
    <collision name="collision">
      <geometry>
        <box>
          <size>0.27069 0.01 0.01</size>
        </box> 
      </geometry>
    </collision>
    <visual name = "visual">
      <pose> 0 0 0 0 1.57075 0 </pose>
      <geometry>
        <cylinder>
          <radius>0.005</radius>
          <length>0.27069</length>
        </cylinder> 
      </geometry>
      <material>
      <script>
        <name>Gazebo/DarkGrey</name>
        <uri>file://media/materials/scripts/gazebo.material</uri>
      </script>
      <shader type='pixel'>
        <normal_map>__default__</normal_map>
      </shader>
      <ambient>0.175 0.175 0.175 1</ambient>
      <diffuse>0.175 0.175 0.175 1</diffuse>
      <specular>0.175 0.175 0.175 1</specular>
      <emissive>0 0 0 1</emissive>
    </material>
    </visual>
  </link>

  <link name="platform_link">
  <gravity>false</gravity>
    <pose>0 0 0.23732941839520943 0 0 0</pose>
    <inertial>
    <mass>0.12</mass>
    <inertia>
      <ixx>7.599999960000001e-05</ixx>
      <ixy>0.0</ixy>
      <ixz>0.0</ixz>
      <iyy>7.599999960000001e-05</iyy> 
      <iyz>0.0</iyz>
      <izz>0.00015000000000000001</izz>
    </inertia>
    </inertial>
    <collision name="collision">
      <geometry>
        <cylinder>
          <radius>0.0625</radius>
          <length>0.01</length>
        </cylinder>  
      </geometry>
    </collision>
    <visual name = "visual">
      <geometry>
        <cylinder>
          <radius>0.0625</radius>
          <length>0.01</length>
        </cylinder> 
      </geometry>
      <material>
      <script>
        <name>Gazebo/DarkGrey</name>
        <uri>file://media/materials/scripts/gazebo.material</uri>
      </script>
      <shader type='pixel'>
        <normal_map>__default__</normal_map>
      </shader>
      <ambient>0.175 0.175 0.175 1</ambient>
      <diffuse>0.175 0.175 0.175 1</diffuse>
      <specular>0.175 0.175 0.175 1</specular>
      <emissive>0 0 0 1</emissive>
    </material>
    </visual>
  </link>

  <plugin name="p3d_base_controller" filename="libgazebo_ros_p3d.so">
  <alwaysOn>true</alwaysOn>
  <updateRate>100.0</updateRate>
  <bodyName>platform_link</bodyName>
  <topicName>ground_truth/tooltip</topicName>
  <gaussianNoise>0.0</gaussianNoise>
  <frameName>map</frameName>
  <xyzOffsets>0 0 0</xyzOffsets>
  <rpyOffsets>0 0 0</rpyOffsets>
</plugin>
</model>
</sdf>